<!-- Cheetah Model
    The state space is populated with joints in the order that they are
    defined in this file. The actuators also operate on joints.
    State-Space (name/joint/parameter):
        - rootx0     slider      position (m)
        - rootz0     slider      position (m)
        - rooty0     hinge       angle (rad)
        - bthigh0    hinge       angle (rad)
        - bshin0     hinge       angle (rad)
        - bfoot0     hinge       angle (rad)
        - fthigh0    hinge       angle (rad)
        - fshin0     hinge       angle (rad)
        - ffoot0     hinge       angle (rad)
        - rootx1     slider      position (m)
        - rootz1     slider      position (m)
        - rooty1     hinge       angle (rad)
        - bthigh1    hinge       angle (rad)
        - bshin1     hinge       angle (rad)
        - bfoot1     hinge       angle (rad)
        - fthigh1    hinge       angle (rad)
        - fshin1     hinge       angle (rad)
        - ffoot1     hinge       angle (rad)
        - rootx0     slider      velocity (m/s)
        - rootz0     slider      velocity (m/s)
        - rooty0     hinge       angular velocity (rad/s)
        - bthigh0    hinge       angular velocity (rad/s)
        - bshin0     hinge       angular velocity (rad/s)
        - bfoot0     hinge       angular velocity (rad/s)
        - fthigh0    hinge       angular velocity (rad/s)
        - fshin0     hinge       angular velocity (rad/s)
        - ffoot0     hinge       angular velocity (rad/s)
        - rootx1     slider      velocity (m/s)
        - rootz1     slider      velocity (m/s)
        - rooty1     hinge       angular velocity (rad/s)
        - bthigh1    hinge       angular velocity (rad/s)
        - bshin1     hinge       angular velocity (rad/s)
        - bfoot1     hinge       angular velocity (rad/s)
        - fthigh1    hinge       angular velocity (rad/s)
        - fshin1     hinge       angular velocity (rad/s)
        - ffoot1     hinge       angular velocity (rad/s)
    Actuators (name/actuator/parameter):
        - bthigh0    hinge       torque (N m)
        - bshin0     hinge       torque (N m)
        - bfoot0     hinge       torque (N m)
        - fthigh0    hinge       torque (N m)
        - fshin0     hinge       torque (N m)
        - ffoot0     hinge       torque (N m)
        - bthigh1    hinge       torque (N m)
        - bshin1     hinge       torque (N m)
        - bfoot1     hinge       torque (N m)
        - fthigh1    hinge       torque (N m)
        - fshin1     hinge       torque (N m)
        - ffoot1     hinge       torque (N m)
-->
<mujoco model="coupled_cheetah">
  <compiler angle="radian" coordinate="local" inertiafromgeom="true" settotalmass="14"/>
  <default>
    <joint armature=".1" damping=".01" limited="true" solimplimit="0 .8 .03" solreflimit=".02 1" stiffness="8"/>
    <geom conaffinity="0" condim="3" contype="1" friction=".4 .1 .1" rgba="0.8 0.6 .4 1" solimp="0.0 0.8 0.01" solref="0.02 1"/>
    <motor ctrllimited="true" ctrlrange="-1 1"/>
  </default>
  <size nstack="300000" nuser_geom="1"/>
  <option gravity="0 0 -9.81" timestep="0.01"/>
  <asset>
    <texture builtin="gradient" height="100" rgb1="1 1 1" rgb2="0 0 0" type="skybox" width="100"/>
    <texture builtin="flat" height="1278" mark="cross" markrgb="1 1 1" name="texgeom" random="0.01" rgb1="0.8 0.6 0.4" rgb2="0.8 0.6 0.4" type="cube" width="127"/>
    <texture builtin="checker" height="100" name="texplane" rgb1="0 0 0" rgb2="0.8 0.8 0.8" type="2d" width="100"/>
    <material name="MatPlane" reflectance="0.5" shininess="1" specular="1" texrepeat="60 60" texture="texplane"/>
    <material name="geom" texture="texgeom" texuniform="true"/>
  </asset>
  <worldbody>
    <light cutoff="100" diffuse="1 1 1" dir="-0 0 -1.3" directional="true" exponent="1" pos="0 0 1.3" specular=".1 .1 .1"/>
    <geom conaffinity="1" condim="3" material="MatPlane" name="floor" pos="0 0 0" rgba="0.8 0.9 0.8 1" size="40 40 40" type="plane"/>
    <body name="torso0" pos="0 -1 .7">
      <site name="t0" pos="0.0 0 0" size="0.1"/>
      <camera name="track0" mode="trackcom" pos="0 -3 0.3" xyaxes="1 0 0 0 0 1"/>
      <joint armature="0" axis="1 0 0" damping="0" limited="false" name="rootx0" pos="0 0 0" stiffness="0" type="slide"/>
      <joint armature="0" axis="0 0 1" damping="0" limited="false" name="rootz0" pos="0 0 0" stiffness="0" type="slide"/>
      <joint armature="0" axis="0 1 0" damping="0" limited="false" name="rooty0" pos="0 0 0" stiffness="0" type="hinge"/>
      <geom fromto="-.5 0 0 .5 0 0" name="torso0" size="0.046" type="capsule"/>
      <geom axisangle="0 1 0 .87" name="head0" pos=".6 0 .1" size="0.046 .15" type="capsule"/>
      <body name="bthigh0" pos="-.5 0 0">
        <joint axis="0 1 0" damping="6" name="bthigh0" pos="0 0 0" range="-.52 1.05" stiffness="240" type="hinge"/>
        <geom axisangle="0 1 0 -3.8" name="bthigh0" pos=".1 0 -.13" size="0.046 .145" type="capsule"/>
        <body name="bshin0" pos=".16 0 -.25">
          <joint axis="0 1 0" damping="4.5" name="bshin0" pos="0 0 0" range="-.785 .785" stiffness="180" type="hinge"/>
          <geom axisangle="0 1 0 -2.03" name="bshin0" pos="-.14 0 -.07" rgba="0.9 0.6 0.6 1" size="0.046 .15" type="capsule"/>
          <body name="bfoot0" pos="-.28 0 -.14">
            <joint axis="0 1 0" damping="3" name="bfoot0" pos="0 0 0" range="-.4 .785" stiffness="120" type="hinge"/>
            <geom axisangle="0 1 0 -.27" name="bfoot0" pos=".03 0 -.097" rgba="0.9 0.6 0.6 1" size="0.046 .094" type="capsule"/>
          </body>
        </body>
      </body>
      <body name="fthigh0" pos=".5 0 0">
        <joint axis="0 1 0" damping="4.5" name="fthigh0" pos="0 0 0" range="-1 .7" stiffness="180" type="hinge"/>
        <geom axisangle="0 1 0 .52" name="fthigh0" pos="-.07 0 -.12" size="0.046 .133" type="capsule"/>
        <body name="fshin0" pos="-.14 0 -.24">
          <joint axis="0 1 0" damping="3" name="fshin0" pos="0 0 0" range="-1.2 .87" stiffness="120" type="hinge"/>
          <geom axisangle="0 1 0 -.6" name="fshin0" pos=".065 0 -.09" rgba="0.9 0.6 0.6 1" size="0.046 .106" type="capsule"/>
          <body name="ffoot0" pos=".13 0 -.18">
            <joint axis="0 1 0" damping="1.5" name="ffoot0" pos="0 0 0" range="-.5 .5" stiffness="60" type="hinge"/>
            <geom axisangle="0 1 0 -.6" name="ffoot0" pos=".045 0 -.07" rgba="0.9 0.6 0.6 1" size="0.046 .07" type="capsule"/>
          </body>
        </body>
      </body>
    </body>
    <!-- second cheetah definition -->
    <body name="torso1" pos="0 1 .7">
      <site name="t1" pos="0 0 0" size="0.1"/>
      <camera name="track1" mode="trackcom" pos="0 -3 0.3" xyaxes="1 0 0 0 0 1"/>
      <joint armature="0" axis="1 0 0" damping="0" limited="false" name="rootx1" pos="0 0 0" stiffness="0" type="slide"/>
      <joint armature="0" axis="0 0 1" damping="0" limited="false" name="rootz1" pos="0 0 0" stiffness="0" type="slide"/>
      <joint armature="0" axis="0 1 0" damping="0" limited="false" name="rooty1" pos="0 0 0" stiffness="0" type="hinge"/>
      <geom fromto="-.5 0 0 .5 0 0" name="torso1" size="0.046" type="capsule"/>
      <geom axisangle="0 1 0 .87" name="head1" pos=".6 0 .1" size="0.046 .15" type="capsule"/>
      <body name="bthigh1" pos="-.5 0 0">
        <joint axis="0 1 0" damping="6" name="bthigh1" pos="0 0 0" range="-.52 1.05" stiffness="240" type="hinge"/>
        <geom axisangle="0 1 0 -3.8" name="bthigh1" pos=".1 0 -.13" size="0.046 .145" type="capsule"/>
        <body name="bshin1" pos=".16 0 -.25">
          <joint axis="0 1 0" damping="4.5" name="bshin1" pos="0 0 0" range="-.785 .785" stiffness="180" type="hinge"/>
          <geom axisangle="0 1 0 -2.03" name="bshin1" pos="-.14 0 -.07" rgba="0.9 0.6 0.6 1" size="0.046 .15" type="capsule"/>
          <body name="bfoot1" pos="-.28 0 -.14">
            <joint axis="0 1 0" damping="3" name="bfoot1" pos="0 0 0" range="-.4 .785" stiffness="120" type="hinge"/>
            <geom axisangle="0 1 0 -.27" name="bfoot1" pos=".03 0 -.097" rgba="0.9 0.6 0.6 1" size="0.046 .094" type="capsule"/>
          </body>
        </body>
      </body>
      <body name="fthigh1" pos=".5 0 0">
        <joint axis="0 1 0" damping="4.5" name="fthigh1" pos="0 0 0" range="-1 .7" stiffness="180" type="hinge"/>
        <geom axisangle="0 1 0 .52" name="fthigh1" pos="-.07 0 -.12" size="0.046 .133" type="capsule"/>
        <body name="fshin1" pos="-.14 0 -.24">
          <joint axis="0 1 0" damping="3" name="fshin1" pos="0 0 0" range="-1.2 .87" stiffness="120" type="hinge"/>
          <geom axisangle="0 1 0 -.6" name="fshin1" pos=".065 0 -.09" rgba="0.9 0.6 0.6 1" size="0.046 .106" type="capsule"/>
          <body name="ffoot1" pos=".13 0 -.18">
            <joint axis="0 1 0" damping="1.5" name="ffoot1" pos="0 0 0" range="-.5 .5" stiffness="60" type="hinge"/>
            <geom axisangle="0 1 0 -.6" name="ffoot1" pos=".045 0 -.07" rgba="0.9 0.6 0.6 1" size="0.046 .07" type="capsule"/>
          </body>
        </body>
      </body>
    </body>
  </worldbody>
  <tendon>
    <spatial name="tendon0" width="0.05" rgba=".95 .3 .3 1" limited="true" range="1.5 3.5" stiffness="0.1">
        <site site="t0"/>
        <site site="t1"/>
    </spatial>
  </tendon>-
  <actuator>
    <motor gear="120" joint="bthigh0" name="bthigh0"/>
    <motor gear="90" joint="bshin0" name="bshin0"/>
    <motor gear="60" joint="bfoot0" name="bfoot0"/>
    <motor gear="120" joint="fthigh0" name="fthigh0"/>
    <motor gear="60" joint="fshin0" name="fshin0"/>
    <motor gear="30" joint="ffoot0" name="ffoot0"/>
    <motor gear="120" joint="bthigh1" name="bthigh1"/>
    <motor gear="90" joint="bshin1" name="bshin1"/>
    <motor gear="60" joint="bfoot1" name="bfoot1"/>
    <motor gear="120" joint="fthigh1" name="fthigh1"/>
    <motor gear="60" joint="fshin1" name="fshin1"/>
    <motor gear="30" joint="ffoot1" name="ffoot1"/>
  </actuator>
</mujoco>